Watching for file changes with StatReloader
Performing system checks...

System check identified no issues (0 silenced).

You have 18 unapplied migration(s). Your project may not work properly until you apply the migrations for app(s): admin, auth, contenttypes, sessions.
Run 'python manage.py migrate' to apply them.
July 06, 2023 - 13:40:10
Django version 3.2.12, using settings 'zura.settings'
Starting development server at http://0.0.0.0:8000/
Quit the server with CONTROL-C.
Error: That port is already in use.
Watching for file changes with StatReloader
Performing system checks...

System check identified no issues (0 silenced).

You have 18 unapplied migration(s). Your project may not work properly until you apply the migrations for app(s): admin, auth, contenttypes, sessions.
Run 'python manage.py migrate' to apply them.
July 06, 2023 - 13:41:06
Django version 3.2.12, using settings 'zura.settings'
Starting development server at http://0.0.0.0:8000/
Quit the server with CONTROL-C.
Error: That port is already in use.
Watching for file changes with StatReloader
Performing system checks...

System check identified no issues (0 silenced).
Exception in thread django-main-thread:
Traceback (most recent call last):
  File "/usr/lib/python3/dist-packages/django/db/backends/base/base.py", line 219, in ensure_connection
    self.connect()
  File "/usr/lib/python3/dist-packages/django/utils/asyncio.py", line 33, in inner
    return func(*args, **kwargs)
  File "/usr/lib/python3/dist-packages/django/db/backends/base/base.py", line 200, in connect
    self.connection = self.get_new_connection(conn_params)
  File "/usr/lib/python3/dist-packages/django/utils/asyncio.py", line 33, in inner
    return func(*args, **kwargs)
  File "/usr/lib/python3/dist-packages/django/db/backends/postgresql/base.py", line 187, in get_new_connection
    connection = Database.connect(**conn_params)
  File "/usr/local/lib/python3.10/dist-packages/psycopg2/__init__.py", line 122, in connect
    conn = _connect(dsn, connection_factory=connection_factory, **kwasync)
psycopg2.OperationalError: connection to server at "localhost" (127.0.0.1), port 5432 failed: Connection refused
	Is the server running on that host and accepting TCP/IP connections?


The above exception was the direct cause of the following exception:

Traceback (most recent call last):
  File "/usr/lib/python3.10/threading.py", line 1016, in _bootstrap_inner
    self.run()
  File "/usr/lib/python3.10/threading.py", line 953, in run
    self._target(*self._args, **self._kwargs)
  File "/usr/lib/python3/dist-packages/django/utils/autoreload.py", line 64, in wrapper
    fn(*args, **kwargs)
  File "/usr/lib/python3/dist-packages/django/core/management/commands/runserver.py", line 121, in inner_run
    self.check_migrations()
  File "/usr/lib/python3/dist-packages/django/core/management/base.py", line 486, in check_migrations
    executor = MigrationExecutor(connections[DEFAULT_DB_ALIAS])
  File "/usr/lib/python3/dist-packages/django/db/migrations/executor.py", line 18, in __init__
    self.loader = MigrationLoader(self.connection)
  File "/usr/lib/python3/dist-packages/django/db/migrations/loader.py", line 53, in __init__
    self.build_graph()
  File "/usr/lib/python3/dist-packages/django/db/migrations/loader.py", line 220, in build_graph
    self.applied_migrations = recorder.applied_migrations()
  File "/usr/lib/python3/dist-packages/django/db/migrations/recorder.py", line 77, in applied_migrations
    if self.has_table():
  File "/usr/lib/python3/dist-packages/django/db/migrations/recorder.py", line 55, in has_table
    with self.connection.cursor() as cursor:
  File "/usr/lib/python3/dist-packages/django/utils/asyncio.py", line 33, in inner
    return func(*args, **kwargs)
  File "/usr/lib/python3/dist-packages/django/db/backends/base/base.py", line 259, in cursor
    return self._cursor()
  File "/usr/lib/python3/dist-packages/django/db/backends/base/base.py", line 235, in _cursor
    self.ensure_connection()
  File "/usr/lib/python3/dist-packages/django/utils/asyncio.py", line 33, in inner
    return func(*args, **kwargs)
  File "/usr/lib/python3/dist-packages/django/db/backends/base/base.py", line 218, in ensure_connection
    with self.wrap_database_errors:
  File "/usr/lib/python3/dist-packages/django/db/utils.py", line 90, in __exit__
    raise dj_exc_value.with_traceback(traceback) from exc_value
  File "/usr/lib/python3/dist-packages/django/db/backends/base/base.py", line 219, in ensure_connection
    self.connect()
  File "/usr/lib/python3/dist-packages/django/utils/asyncio.py", line 33, in inner
    return func(*args, **kwargs)
  File "/usr/lib/python3/dist-packages/django/db/backends/base/base.py", line 200, in connect
    self.connection = self.get_new_connection(conn_params)
  File "/usr/lib/python3/dist-packages/django/utils/asyncio.py", line 33, in inner
    return func(*args, **kwargs)
  File "/usr/lib/python3/dist-packages/django/db/backends/postgresql/base.py", line 187, in get_new_connection
    connection = Database.connect(**conn_params)
  File "/usr/local/lib/python3.10/dist-packages/psycopg2/__init__.py", line 122, in connect
    conn = _connect(dsn, connection_factory=connection_factory, **kwasync)
django.db.utils.OperationalError: connection to server at "localhost" (127.0.0.1), port 5432 failed: Connection refused
	Is the server running on that host and accepting TCP/IP connections?

Watching for file changes with StatReloader
Performing system checks...

System check identified no issues (0 silenced).
Exception in thread django-main-thread:
Traceback (most recent call last):
  File "/usr/lib/python3/dist-packages/django/db/backends/base/base.py", line 219, in ensure_connection
    self.connect()
  File "/usr/lib/python3/dist-packages/django/utils/asyncio.py", line 33, in inner
    return func(*args, **kwargs)
  File "/usr/lib/python3/dist-packages/django/db/backends/base/base.py", line 200, in connect
    self.connection = self.get_new_connection(conn_params)
  File "/usr/lib/python3/dist-packages/django/utils/asyncio.py", line 33, in inner
    return func(*args, **kwargs)
  File "/usr/lib/python3/dist-packages/django/db/backends/postgresql/base.py", line 187, in get_new_connection
    connection = Database.connect(**conn_params)
  File "/usr/local/lib/python3.10/dist-packages/psycopg2/__init__.py", line 122, in connect
    conn = _connect(dsn, connection_factory=connection_factory, **kwasync)
psycopg2.OperationalError: connection to server at "localhost" (127.0.0.1), port 5432 failed: Connection refused
	Is the server running on that host and accepting TCP/IP connections?


The above exception was the direct cause of the following exception:

Traceback (most recent call last):
  File "/usr/lib/python3.10/threading.py", line 1016, in _bootstrap_inner
    self.run()
  File "/usr/lib/python3.10/threading.py", line 953, in run
    self._target(*self._args, **self._kwargs)
  File "/usr/lib/python3/dist-packages/django/utils/autoreload.py", line 64, in wrapper
    fn(*args, **kwargs)
  File "/usr/lib/python3/dist-packages/django/core/management/commands/runserver.py", line 121, in inner_run
    self.check_migrations()
  File "/usr/lib/python3/dist-packages/django/core/management/base.py", line 486, in check_migrations
    executor = MigrationExecutor(connections[DEFAULT_DB_ALIAS])
  File "/usr/lib/python3/dist-packages/django/db/migrations/executor.py", line 18, in __init__
    self.loader = MigrationLoader(self.connection)
  File "/usr/lib/python3/dist-packages/django/db/migrations/loader.py", line 53, in __init__
    self.build_graph()
  File "/usr/lib/python3/dist-packages/django/db/migrations/loader.py", line 220, in build_graph
    self.applied_migrations = recorder.applied_migrations()
  File "/usr/lib/python3/dist-packages/django/db/migrations/recorder.py", line 77, in applied_migrations
    if self.has_table():
  File "/usr/lib/python3/dist-packages/django/db/migrations/recorder.py", line 55, in has_table
    with self.connection.cursor() as cursor:
  File "/usr/lib/python3/dist-packages/django/utils/asyncio.py", line 33, in inner
    return func(*args, **kwargs)
  File "/usr/lib/python3/dist-packages/django/db/backends/base/base.py", line 259, in cursor
    return self._cursor()
  File "/usr/lib/python3/dist-packages/django/db/backends/base/base.py", line 235, in _cursor
    self.ensure_connection()
  File "/usr/lib/python3/dist-packages/django/utils/asyncio.py", line 33, in inner
    return func(*args, **kwargs)
  File "/usr/lib/python3/dist-packages/django/db/backends/base/base.py", line 218, in ensure_connection
    with self.wrap_database_errors:
  File "/usr/lib/python3/dist-packages/django/db/utils.py", line 90, in __exit__
    raise dj_exc_value.with_traceback(traceback) from exc_value
  File "/usr/lib/python3/dist-packages/django/db/backends/base/base.py", line 219, in ensure_connection
    self.connect()
  File "/usr/lib/python3/dist-packages/django/utils/asyncio.py", line 33, in inner
    return func(*args, **kwargs)
  File "/usr/lib/python3/dist-packages/django/db/backends/base/base.py", line 200, in connect
    self.connection = self.get_new_connection(conn_params)
  File "/usr/lib/python3/dist-packages/django/utils/asyncio.py", line 33, in inner
    return func(*args, **kwargs)
  File "/usr/lib/python3/dist-packages/django/db/backends/postgresql/base.py", line 187, in get_new_connection
    connection = Database.connect(**conn_params)
  File "/usr/local/lib/python3.10/dist-packages/psycopg2/__init__.py", line 122, in connect
    conn = _connect(dsn, connection_factory=connection_factory, **kwasync)
django.db.utils.OperationalError: connection to server at "localhost" (127.0.0.1), port 5432 failed: Connection refused
	Is the server running on that host and accepting TCP/IP connections?

Watching for file changes with StatReloader
Performing system checks...

System check identified no issues (0 silenced).
Exception in thread django-main-thread:
Traceback (most recent call last):
  File "/usr/lib/python3/dist-packages/django/db/backends/base/base.py", line 219, in ensure_connection
    self.connect()
  File "/usr/lib/python3/dist-packages/django/utils/asyncio.py", line 33, in inner
    return func(*args, **kwargs)
  File "/usr/lib/python3/dist-packages/django/db/backends/base/base.py", line 200, in connect
    self.connection = self.get_new_connection(conn_params)
  File "/usr/lib/python3/dist-packages/django/utils/asyncio.py", line 33, in inner
    return func(*args, **kwargs)
  File "/usr/lib/python3/dist-packages/django/db/backends/postgresql/base.py", line 187, in get_new_connection
    connection = Database.connect(**conn_params)
  File "/usr/local/lib/python3.10/dist-packages/psycopg2/__init__.py", line 122, in connect
    conn = _connect(dsn, connection_factory=connection_factory, **kwasync)
psycopg2.OperationalError: connection to server at "localhost" (127.0.0.1), port 5432 failed: Connection refused
	Is the server running on that host and accepting TCP/IP connections?


The above exception was the direct cause of the following exception:

Traceback (most recent call last):
  File "/usr/lib/python3.10/threading.py", line 1016, in _bootstrap_inner
    self.run()
  File "/usr/lib/python3.10/threading.py", line 953, in run
    self._target(*self._args, **self._kwargs)
  File "/usr/lib/python3/dist-packages/django/utils/autoreload.py", line 64, in wrapper
    fn(*args, **kwargs)
  File "/usr/lib/python3/dist-packages/django/core/management/commands/runserver.py", line 121, in inner_run
    self.check_migrations()
  File "/usr/lib/python3/dist-packages/django/core/management/base.py", line 486, in check_migrations
    executor = MigrationExecutor(connections[DEFAULT_DB_ALIAS])
  File "/usr/lib/python3/dist-packages/django/db/migrations/executor.py", line 18, in __init__
    self.loader = MigrationLoader(self.connection)
  File "/usr/lib/python3/dist-packages/django/db/migrations/loader.py", line 53, in __init__
    self.build_graph()
  File "/usr/lib/python3/dist-packages/django/db/migrations/loader.py", line 220, in build_graph
    self.applied_migrations = recorder.applied_migrations()
  File "/usr/lib/python3/dist-packages/django/db/migrations/recorder.py", line 77, in applied_migrations
    if self.has_table():
  File "/usr/lib/python3/dist-packages/django/db/migrations/recorder.py", line 55, in has_table
    with self.connection.cursor() as cursor:
  File "/usr/lib/python3/dist-packages/django/utils/asyncio.py", line 33, in inner
    return func(*args, **kwargs)
  File "/usr/lib/python3/dist-packages/django/db/backends/base/base.py", line 259, in cursor
    return self._cursor()
  File "/usr/lib/python3/dist-packages/django/db/backends/base/base.py", line 235, in _cursor
    self.ensure_connection()
  File "/usr/lib/python3/dist-packages/django/utils/asyncio.py", line 33, in inner
    return func(*args, **kwargs)
  File "/usr/lib/python3/dist-packages/django/db/backends/base/base.py", line 218, in ensure_connection
    with self.wrap_database_errors:
  File "/usr/lib/python3/dist-packages/django/db/utils.py", line 90, in __exit__
    raise dj_exc_value.with_traceback(traceback) from exc_value
  File "/usr/lib/python3/dist-packages/django/db/backends/base/base.py", line 219, in ensure_connection
    self.connect()
  File "/usr/lib/python3/dist-packages/django/utils/asyncio.py", line 33, in inner
    return func(*args, **kwargs)
  File "/usr/lib/python3/dist-packages/django/db/backends/base/base.py", line 200, in connect
    self.connection = self.get_new_connection(conn_params)
  File "/usr/lib/python3/dist-packages/django/utils/asyncio.py", line 33, in inner
    return func(*args, **kwargs)
  File "/usr/lib/python3/dist-packages/django/db/backends/postgresql/base.py", line 187, in get_new_connection
    connection = Database.connect(**conn_params)
  File "/usr/local/lib/python3.10/dist-packages/psycopg2/__init__.py", line 122, in connect
    conn = _connect(dsn, connection_factory=connection_factory, **kwasync)
django.db.utils.OperationalError: connection to server at "localhost" (127.0.0.1), port 5432 failed: Connection refused
	Is the server running on that host and accepting TCP/IP connections?

Watching for file changes with StatReloader
Performing system checks...

System check identified no issues (0 silenced).

You have 18 unapplied migration(s). Your project may not work properly until you apply the migrations for app(s): admin, auth, contenttypes, sessions.
Run 'python manage.py migrate' to apply them.
July 06, 2023 - 14:09:10
Django version 3.2.12, using settings 'zura.settings'
Starting development server at http://0.0.0.0:8000/
Quit the server with CONTROL-C.
[06/Jul/2023 14:09:41] "GET / HTTP/1.1" 200 10697
[06/Jul/2023 14:09:41] "GET /static/admin/css/fonts.css HTTP/1.1" 200 423
[06/Jul/2023 14:09:41] "GET /static/admin/fonts/Roboto-Regular-webfont.woff HTTP/1.1" 200 85876
[06/Jul/2023 14:09:41] "GET /static/admin/fonts/Roboto-Bold-webfont.woff HTTP/1.1" 200 86184
[06/Jul/2023 14:09:41] "GET /static/admin/fonts/Roboto-Light-webfont.woff HTTP/1.1" 200 85692
[06/Jul/2023 14:09:58] "GET / HTTP/1.1" 200 10697
[06/Jul/2023 14:10:12] "GET /admin HTTP/1.1" 301 0
[06/Jul/2023 14:10:12] "GET /admin/ HTTP/1.1" 302 0
[06/Jul/2023 14:10:12] "GET /admin/login/?next=/admin/ HTTP/1.1" 200 2214
[06/Jul/2023 14:10:12] "GET /static/admin/css/login.css HTTP/1.1" 200 939
[06/Jul/2023 14:10:12] "GET /static/admin/js/nav_sidebar.js HTTP/1.1" 200 1360
[06/Jul/2023 14:10:12] "GET /static/admin/css/nav_sidebar.css HTTP/1.1" 200 2271
[06/Jul/2023 14:10:12] "GET /static/admin/css/base.css HTTP/1.1" 200 19513
[06/Jul/2023 14:10:12] "GET /static/admin/css/responsive.css HTTP/1.1" 200 18545
Internal Server Error: /admin/login/
Traceback (most recent call last):
  File "/usr/lib/python3/dist-packages/django/db/backends/utils.py", line 84, in _execute
    return self.cursor.execute(sql, params)
psycopg2.errors.UndefinedTable: relation "auth_user" does not exist
LINE 1: ...user"."is_active", "auth_user"."date_joined" FROM "auth_user...
                                                             ^


The above exception was the direct cause of the following exception:

Traceback (most recent call last):
  File "/usr/lib/python3/dist-packages/django/core/handlers/exception.py", line 47, in inner
    response = get_response(request)
  File "/usr/lib/python3/dist-packages/django/core/handlers/base.py", line 181, in _get_response
    response = wrapped_callback(request, *callback_args, **callback_kwargs)
  File "/usr/lib/python3/dist-packages/django/views/decorators/cache.py", line 44, in _wrapped_view_func
    response = view_func(request, *args, **kwargs)
  File "/usr/lib/python3/dist-packages/django/contrib/admin/sites.py", line 414, in login
    return LoginView.as_view(**defaults)(request)
  File "/usr/lib/python3/dist-packages/django/views/generic/base.py", line 70, in view
    return self.dispatch(request, *args, **kwargs)
  File "/usr/lib/python3/dist-packages/django/utils/decorators.py", line 43, in _wrapper
    return bound_method(*args, **kwargs)
  File "/usr/lib/python3/dist-packages/django/views/decorators/debug.py", line 89, in sensitive_post_parameters_wrapper
    return view(request, *args, **kwargs)
  File "/usr/lib/python3/dist-packages/django/utils/decorators.py", line 43, in _wrapper
    return bound_method(*args, **kwargs)
  File "/usr/lib/python3/dist-packages/django/utils/decorators.py", line 130, in _wrapped_view
    response = view_func(request, *args, **kwargs)
  File "/usr/lib/python3/dist-packages/django/utils/decorators.py", line 43, in _wrapper
    return bound_method(*args, **kwargs)
  File "/usr/lib/python3/dist-packages/django/views/decorators/cache.py", line 44, in _wrapped_view_func
    response = view_func(request, *args, **kwargs)
  File "/usr/lib/python3/dist-packages/django/contrib/auth/views.py", line 63, in dispatch
    return super().dispatch(request, *args, **kwargs)
  File "/usr/lib/python3/dist-packages/django/views/generic/base.py", line 98, in dispatch
    return handler(request, *args, **kwargs)
  File "/usr/lib/python3/dist-packages/django/views/generic/edit.py", line 141, in post
    if form.is_valid():
  File "/usr/lib/python3/dist-packages/django/forms/forms.py", line 175, in is_valid
    return self.is_bound and not self.errors
  File "/usr/lib/python3/dist-packages/django/forms/forms.py", line 170, in errors
    self.full_clean()
  File "/usr/lib/python3/dist-packages/django/forms/forms.py", line 373, in full_clean
    self._clean_form()
  File "/usr/lib/python3/dist-packages/django/forms/forms.py", line 400, in _clean_form
    cleaned_data = self.clean()
  File "/usr/lib/python3/dist-packages/django/contrib/auth/forms.py", line 202, in clean
    self.user_cache = authenticate(self.request, username=username, password=password)
  File "/usr/lib/python3/dist-packages/django/views/decorators/debug.py", line 42, in sensitive_variables_wrapper
    return func(*func_args, **func_kwargs)
  File "/usr/lib/python3/dist-packages/django/contrib/auth/__init__.py", line 76, in authenticate
    user = backend.authenticate(request, **credentials)
  File "/usr/lib/python3/dist-packages/django/contrib/auth/backends.py", line 42, in authenticate
    user = UserModel._default_manager.get_by_natural_key(username)
  File "/usr/lib/python3/dist-packages/django/contrib/auth/base_user.py", line 45, in get_by_natural_key
    return self.get(**{self.model.USERNAME_FIELD: username})
  File "/usr/lib/python3/dist-packages/django/db/models/manager.py", line 85, in manager_method
    return getattr(self.get_queryset(), name)(*args, **kwargs)
  File "/usr/lib/python3/dist-packages/django/db/models/query.py", line 431, in get
    num = len(clone)
  File "/usr/lib/python3/dist-packages/django/db/models/query.py", line 262, in __len__
    self._fetch_all()
  File "/usr/lib/python3/dist-packages/django/db/models/query.py", line 1324, in _fetch_all
    self._result_cache = list(self._iterable_class(self))
  File "/usr/lib/python3/dist-packages/django/db/models/query.py", line 51, in __iter__
    results = compiler.execute_sql(chunked_fetch=self.chunked_fetch, chunk_size=self.chunk_size)
  File "/usr/lib/python3/dist-packages/django/db/models/sql/compiler.py", line 1175, in execute_sql
    cursor.execute(sql, params)
  File "/usr/lib/python3/dist-packages/django/db/backends/utils.py", line 98, in execute
    return super().execute(sql, params)
  File "/usr/lib/python3/dist-packages/django/db/backends/utils.py", line 66, in execute
    return self._execute_with_wrappers(sql, params, many=False, executor=self._execute)
  File "/usr/lib/python3/dist-packages/django/db/backends/utils.py", line 75, in _execute_with_wrappers
    return executor(sql, params, many, context)
  File "/usr/lib/python3/dist-packages/django/db/backends/utils.py", line 79, in _execute
    with self.db.wrap_database_errors:
  File "/usr/lib/python3/dist-packages/django/db/utils.py", line 90, in __exit__
    raise dj_exc_value.with_traceback(traceback) from exc_value
  File "/usr/lib/python3/dist-packages/django/db/backends/utils.py", line 84, in _execute
    return self.cursor.execute(sql, params)
django.db.utils.ProgrammingError: relation "auth_user" does not exist
LINE 1: ...user"."is_active", "auth_user"."date_joined" FROM "auth_user...
                                                             ^

[06/Jul/2023 14:10:19] "POST /admin/login/?next=/admin/ HTTP/1.1" 500 216250
[06/Jul/2023 14:15:06] "GET / HTTP/1.1" 200 10697
